const f = () => {
  try {
    console.log("Programm is successfyully run bhai")
    // return
    console.log(jeet)
  } catch (err) {
    consol.log("This is an error" .err)
    // console.log(12)
  
  } finally {
    // console.log("Finally your program is successfully run")
  }
}

f()
